[NbConvertApp] Converting notebook copyme.ipynb to notebook
[NbConvertApp] Executing notebook with kernel: python2
[IPKernelApp] ERROR | Failed to open SQLite history /home/mazeau.e/.ipython/profile_default/history.sqlite (database disk image is malformed).
Traceback (most recent call last):
  File "/home/mazeau.e/anaconda2/envs/rmg_env/lib/python2.7/runpy.py", line 174, in _run_module_as_main
    "__main__", fname, loader, pkg_name)
  File "/home/mazeau.e/anaconda2/envs/rmg_env/lib/python2.7/runpy.py", line 72, in _run_code
    exec code in run_globals
  File "/home/mazeau.e/anaconda2/envs/rmg_env/lib/python2.7/site-packages/ipykernel_launcher.py", line 16, in <module>
    app.launch_new_instance()
  File "/home/mazeau.e/anaconda2/envs/rmg_env/lib/python2.7/site-packages/traitlets/config/application.py", line 657, in launch_instance
    app.initialize(argv)
  File "<decorator-gen-121>", line 2, in initialize
  File "/home/mazeau.e/anaconda2/envs/rmg_env/lib/python2.7/site-packages/traitlets/config/application.py", line 87, in catch_config_error
    return method(app, *args, **kwargs)
  File "/home/mazeau.e/anaconda2/envs/rmg_env/lib/python2.7/site-packages/ipykernel/kernelapp.py", line 476, in initialize
    self.init_kernel()
  File "/home/mazeau.e/anaconda2/envs/rmg_env/lib/python2.7/site-packages/ipykernel/kernelapp.py", line 387, in init_kernel
    user_ns=self.user_ns,
  File "/home/mazeau.e/anaconda2/envs/rmg_env/lib/python2.7/site-packages/traitlets/config/configurable.py", line 412, in instance
    inst = cls(*args, **kwargs)
  File "/home/mazeau.e/anaconda2/envs/rmg_env/lib/python2.7/site-packages/ipykernel/ipkernel.py", line 58, in __init__
    kernel      = self,
  File "/home/mazeau.e/anaconda2/envs/rmg_env/lib/python2.7/site-packages/traitlets/config/configurable.py", line 412, in instance
    inst = cls(*args, **kwargs)
  File "/home/mazeau.e/anaconda2/envs/rmg_env/lib/python2.7/site-packages/IPython/core/interactiveshell.py", line 478, in __init__
    self.init_history()
  File "/home/mazeau.e/anaconda2/envs/rmg_env/lib/python2.7/site-packages/IPython/core/interactiveshell.py", line 1579, in init_history
    self.history_manager = HistoryManager(shell=self, parent=self)
  File "/home/mazeau.e/anaconda2/envs/rmg_env/lib/python2.7/site-packages/IPython/core/history.py", line 543, in __init__
    **traits)
  File "/home/mazeau.e/anaconda2/envs/rmg_env/lib/python2.7/site-packages/IPython/core/history.py", line 231, in __init__
    self.init_db()
  File "<decorator-gen-15>", line 2, in init_db
  File "/home/mazeau.e/anaconda2/envs/rmg_env/lib/python2.7/site-packages/IPython/core/history.py", line 115, in catch_corrupt_db
    os.rename(self.hist_file, newpath)
OSError: [Errno 2] No such file or directory
Traceback (most recent call last):
  File "/home/mazeau.e/anaconda2/envs/rmg_env/bin/jupyter-nbconvert", line 11, in <module>
    sys.exit(main())
  File "/home/mazeau.e/anaconda2/envs/rmg_env/lib/python2.7/site-packages/jupyter_core/application.py", line 266, in launch_instance
    return super(JupyterApp, cls).launch_instance(argv=argv, **kwargs)
  File "/home/mazeau.e/anaconda2/envs/rmg_env/lib/python2.7/site-packages/traitlets/config/application.py", line 658, in launch_instance
    app.start()
  File "/home/mazeau.e/anaconda2/envs/rmg_env/lib/python2.7/site-packages/nbconvert/nbconvertapp.py", line 325, in start
    self.convert_notebooks()
  File "/home/mazeau.e/anaconda2/envs/rmg_env/lib/python2.7/site-packages/nbconvert/nbconvertapp.py", line 493, in convert_notebooks
    self.convert_single_notebook(notebook_filename)
  File "/home/mazeau.e/anaconda2/envs/rmg_env/lib/python2.7/site-packages/nbconvert/nbconvertapp.py", line 464, in convert_single_notebook
    output, resources = self.export_single_notebook(notebook_filename, resources, input_buffer=input_buffer)
  File "/home/mazeau.e/anaconda2/envs/rmg_env/lib/python2.7/site-packages/nbconvert/nbconvertapp.py", line 393, in export_single_notebook
    output, resources = self.exporter.from_filename(notebook_filename, resources=resources)
  File "/home/mazeau.e/anaconda2/envs/rmg_env/lib/python2.7/site-packages/nbconvert/exporters/exporter.py", line 174, in from_filename
    return self.from_file(f, resources=resources, **kw)
  File "/home/mazeau.e/anaconda2/envs/rmg_env/lib/python2.7/site-packages/nbconvert/exporters/exporter.py", line 192, in from_file
    return self.from_notebook_node(nbformat.read(file_stream, as_version=4), resources=resources, **kw)
  File "/home/mazeau.e/anaconda2/envs/rmg_env/lib/python2.7/site-packages/nbconvert/exporters/notebook.py", line 31, in from_notebook_node
    nb_copy, resources = super(NotebookExporter, self).from_notebook_node(nb, resources, **kw)
  File "/home/mazeau.e/anaconda2/envs/rmg_env/lib/python2.7/site-packages/nbconvert/exporters/exporter.py", line 134, in from_notebook_node
    nb_copy, resources = self._preprocess(nb_copy, resources)
  File "/home/mazeau.e/anaconda2/envs/rmg_env/lib/python2.7/site-packages/nbconvert/exporters/exporter.py", line 311, in _preprocess
    nbc, resc = preprocessor(nbc, resc)
  File "/home/mazeau.e/anaconda2/envs/rmg_env/lib/python2.7/site-packages/nbconvert/preprocessors/base.py", line 47, in __call__
    return self.preprocess(nb, resources)
  File "/home/mazeau.e/anaconda2/envs/rmg_env/lib/python2.7/site-packages/nbconvert/preprocessors/execute.py", line 257, in preprocess
    cwd=path)
  File "/home/mazeau.e/anaconda2/envs/rmg_env/lib/python2.7/site-packages/nbconvert/preprocessors/execute.py", line 241, in start_new_kernel
    kc.wait_for_ready(timeout=startup_timeout)
  File "/home/mazeau.e/anaconda2/envs/rmg_env/lib/python2.7/site-packages/jupyter_client/blocking/client.py", line 120, in wait_for_ready
    raise RuntimeError('Kernel died before replying to kernel_info')
RuntimeError: Kernel died before replying to kernel_info
